<sdf version='1.6'>
  <model name='frog_v2'>
    <link name='base_link'>
      <pose>0 0 0 0 -0 0</pose>
      <inertial>
        <pose>-0.002999 0.000926 0.006638 0 -0 0</pose>
        <mass>1.0526</mass>
        <inertia>
          <ixx>0.0019265</ixx>
          <ixy>1.3781e-06</ixy>
          <ixz>1.1574e-07</ixz>
          <iyy>0.0018588</iyy>
          <iyz>1.5461e-09</iyz>
          <izz>0.0036311</izz>
        </inertia>
      </inertial>
      <collision name='base_link_collision'>
        <pose>0 0 0 0 -0 0</pose>
        <geometry>
          <mesh>
            <scale>1 1 1</scale>
            <uri>model://frog_v2/meshes/base_link_col.STL</uri>
          </mesh>
        </geometry>
        <surface>
          <contact>
            <ode>
              <max_vel>100.0</max_vel>
              <min_depth>0.001</min_depth>
            </ode>
          </contact>
          <friction>
            <ode>
              <mu>100000.0</mu>
              <mu2>100000.0</mu2>
            </ode>
          </friction>
        </surface>
      </collision>
      <visual name='base_link_visual'>
        <pose>0 0 0 0 -0 0</pose>
        <geometry>
          <mesh>
            <scale>1 1 1</scale>
            <uri>model://frog_v2/meshes/base_link.STL</uri>
          </mesh>
        </geometry>
      </visual>
    </link>
    <link name='D435'>
      <pose>0.052 0 0.0186 0 -0 0</pose>
      <inertial>
        <pose>-0.000103 0.00041 0.000115 0 -0 0</pose>
        <mass>0.055398</mass>
        <inertia>
          <ixx>4.3008e-05</ixx>
          <ixy>3.1633e-07</ixy>
          <ixz>-1.3724e-07</ixz>
          <iyy>5.2016e-06</iyy>
          <iyz>1.916e-08</iyz>
          <izz>4.2419e-05</izz>
        </inertia>
      </inertial>
      <visual name='D435_visual'>
        <pose>0 0 0 0 -0 0</pose>
        <geometry>
          <mesh>
            <scale>1 1 1</scale>
            <uri>model://frog_v2/meshes/D435.STL</uri>
          </mesh>
        </geometry>
      </visual>
    </link>
    <joint name='D435_joint' type='revolute'>
      <child>D435</child>
      <parent>base_link</parent>
      <axis>
        <xyz>0 1 0</xyz>
        <limit>
          <lower>-0.610865</lower>
          <upper>1.5708</upper>
          <effort>100</effort>
          <velocity>100</velocity>
        </limit>
        <dynamics>
          <damping>0.004</damping>
          <friction>0</friction>
          <spring_reference>0</spring_reference>
          <spring_stiffness>0</spring_stiffness>
        </dynamics>
        <use_parent_model_frame>0</use_parent_model_frame>
      </axis>
    </joint>
    <link name='fpv_cam'>
      <pose>0.092345 -1.7e-05 -0.015 0 0.017453 0</pose>
      <inertial>
        <pose>0.00627 0 -0.00002 0 -0 0</pose>
        <mass>0.006</mass>
        <inertia>
          <ixx>1.1947e-07</ixx>
          <ixy>5.0178e-11</ixy>
          <ixz>1.0715e-09</ixz>
          <iyy>6.5772e-08</iyy>
          <iyz>7.8745e-09</iyz>
          <izz>7.4562e-08</izz>
        </inertia>
      </inertial>
      <visual name='fpv_cam_visual'>
        <pose>0 0 0 0 -0 0</pose>
        <geometry>
          <mesh>
            <scale>1 1 1</scale>
            <uri>model://frog_v2/meshes/fpv_cam.STL</uri>
          </mesh>
        </geometry>
      </visual>
    </link>
    <joint name='fpv_cam_joint' type='revolute'>
      <child>fpv_cam</child>
      <parent>base_link</parent>
      <axis>
        <xyz>0 1 0</xyz>
        <limit>
          <lower>-0.610865</lower>
          <upper>1.5708</upper>
          <effort>100</effort>
          <velocity>100</velocity>
        </limit>
        <dynamics>
          <friction>0</friction>
          <spring_reference>0</spring_reference>
          <spring_stiffness>0</spring_stiffness>
        </dynamics>
        <use_parent_model_frame>0</use_parent_model_frame>
      </axis>
    </joint>
    <link name='prop_1'>
      <pose>0.23937 -0.23937 0.073136 0 -0 1.5708</pose>
      <inertial>
        <pose>-5.7e-05 1.2e-05 -0.000133 0 -0 0</pose>
        <mass>0.03348</mass>
        <inertia>
          <ixx>0.00018526</ixx>
          <ixy>-5.3209e-05</ixy>
          <ixz>2.2443e-07</ixz>
          <iyy>1.7676e-05</iyy>
          <iyz>4.0635e-07</iyz>
          <izz>0.00020271</izz>
        </inertia>
      </inertial>
      <collision name='prop_1_collision'>
        <pose>0 0 0 0 -0 0</pose>
        <geometry>
          <mesh>
            <scale>1 1 1</scale>
            <uri>model://frog_v2/meshes/prop_1_col.STL</uri>
          </mesh>
        </geometry>
      </collision>
      <visual name='prop_1_visual'>
        <pose>0 0 0 0 -0 0</pose>
        <geometry>
          <mesh>
            <scale>1 1 1</scale>
            <uri>model://frog_v2/meshes/prop_1.STL</uri>
          </mesh>
        </geometry>
      </visual>
    </link>
    <joint name='prop_1_joint' type='revolute'>
      <child>prop_1</child>
      <parent>base_link</parent>
      <axis>
        <xyz>0 0 1</xyz>
        <limit>
          <lower>-1e+16</lower>
          <upper>1e+16</upper>
          <effort>100</effort>
          <velocity>100</velocity>
        </limit>
        <dynamics>
          <damping>0.004</damping>
          <friction>0</friction>
          <spring_reference>0</spring_reference>
          <spring_stiffness>0</spring_stiffness>
        </dynamics>
        <use_parent_model_frame>0</use_parent_model_frame>
      </axis>
      <physics>
        <ode>
          <implicit_spring_damper>1</implicit_spring_damper>
        </ode>
      </physics>
    </joint>
    <link name='prop_2'>
      <pose>-0.23937 -0.23937 0.073136 0 -0 1.5708</pose>
      <inertial>
        <pose>-5.7e-05 1.2e-05 -0.000133 0 -0 0</pose>
        <mass>0.03348</mass>
        <inertia>
          <ixx>0.00018526</ixx>
          <ixy>-5.3209e-05</ixy>
          <ixz>2.2443e-07</ixz>
          <iyy>1.7676e-05</iyy>
          <iyz>4.0635e-07</iyz>
          <izz>0.00020271</izz>
        </inertia>
      </inertial>
      <collision name='prop_2_collision'>
        <pose>0 0 0 0 -0 0</pose>
        <geometry>
          <mesh>
            <scale>1 1 1</scale>
            <uri>model://frog_v2/meshes/prop_2_col.STL</uri>
          </mesh>
        </geometry>
      </collision>
      <visual name='prop_2_visual'>
        <pose>0 0 0 0 -0 0</pose>
        <geometry>
          <mesh>
            <scale>1 1 1</scale>
            <uri>model://frog_v2/meshes/prop_2.STL</uri>
          </mesh>
        </geometry>
      </visual>
    </link>
    <joint name='prop_2_joint' type='revolute'>
      <child>prop_2</child>
      <parent>base_link</parent>
      <axis>
        <xyz>0 0 1</xyz>
        <limit>
          <lower>-1e+16</lower>
          <upper>1e+16</upper>
          <effort>100</effort>
          <velocity>100</velocity>
        </limit>
        <dynamics>
          <damping>0.004</damping>
          <friction>0</friction>
          <spring_reference>0</spring_reference>
          <spring_stiffness>0</spring_stiffness>
        </dynamics>
        <use_parent_model_frame>0</use_parent_model_frame>
      </axis>
      <physics>
        <ode>
          <implicit_spring_damper>1</implicit_spring_damper>
        </ode>
      </physics>
    </joint>
    <link name='prop_3'>
      <pose>-0.23937 0.23937 0.073137 0 -0 1.5708</pose>
      <inertial>
        <pose>-5.7e-05 1.2e-05 -0.000133 0 -0 0</pose>
        <mass>0.03348</mass>
        <inertia>
          <ixx>0.00018526</ixx>
          <ixy>-5.3209e-05</ixy>
          <ixz>2.2443e-07</ixz>
          <iyy>1.7676e-05</iyy>
          <iyz>4.0635e-07</iyz>
          <izz>0.00020271</izz>
        </inertia>
      </inertial>
      <collision name='prop_3_collision'>
        <pose>0 0 0 0 -0 0</pose>
        <geometry>
          <mesh>
            <scale>1 1 1</scale>
            <uri>model://frog_v2/meshes/prop_3_col.STL</uri>
          </mesh>
        </geometry>
      </collision>
      <visual name='prop_3_visual'>
        <pose>0 0 0 0 -0 0</pose>
        <geometry>
          <mesh>
            <scale>1 1 1</scale>
            <uri>model://frog_v2/meshes/prop_3.STL</uri>
          </mesh>
        </geometry>
      </visual>
    </link>
    <joint name='prop_3_joint' type='revolute'>
      <child>prop_3</child>
      <parent>base_link</parent>
      <axis>
        <xyz>0 0 1</xyz>
        <limit>
          <lower>-1e+16</lower>
          <upper>1e+16</upper>
          <effort>100</effort>
          <velocity>100</velocity>
        </limit>
        <dynamics>
          <damping>0.004</damping>
          <friction>0</friction>
          <spring_reference>0</spring_reference>
          <spring_stiffness>0</spring_stiffness>
        </dynamics>
        <use_parent_model_frame>0</use_parent_model_frame>
      </axis>
      <physics>
        <ode>
          <implicit_spring_damper>1</implicit_spring_damper>
        </ode>
      </physics>
    </joint>
    <link name='prop_4'>
      <pose>0.23937 0.23937 0.073137 0 -0 1.5708</pose>
      <inertial>
        <pose>-5.7e-05 1.2e-05 -0.000133 0 -0 0</pose>
        <mass>0.03348</mass>
        <inertia>
          <ixx>0.00018526</ixx>
          <ixy>-5.3209e-05</ixy>
          <ixz>2.2443e-07</ixz>
          <iyy>1.7676e-05</iyy>
          <iyz>4.0635e-07</iyz>
          <izz>0.00020271</izz>
        </inertia>
      </inertial>
      <collision name='prop_4_collision'>
        <pose>0 0 0 0 -0 0</pose>
        <geometry>
          <mesh>
            <scale>1 1 1</scale>
            <uri>model://frog_v2/meshes/prop_4_col.STL</uri>
          </mesh>
        </geometry>
      </collision>
      <visual name='prop_4_visual'>
        <pose>0 0 0 0 -0 0</pose>
        <geometry>
          <mesh>
            <scale>1 1 1</scale>
            <uri>model://frog_v2/meshes/prop_4.STL</uri>
          </mesh>
        </geometry>
      </visual>
    </link>
    <joint name='prop_4_joint' type='revolute'>
      <child>prop_4</child>
      <parent>base_link</parent>
      <axis>
        <xyz>0 0 1</xyz>
        <limit>
          <lower>-1e+16</lower>
          <upper>1e+16</upper>
          <effort>100</effort>
          <velocity>100</velocity>
        </limit>
        <dynamics>
          <damping>0.004</damping>
          <friction>0</friction>
          <spring_reference>0</spring_reference>
          <spring_stiffness>0</spring_stiffness>
        </dynamics>
        <use_parent_model_frame>0</use_parent_model_frame>
      </axis>
      <physics>
        <ode>
          <implicit_spring_damper>1</implicit_spring_damper>
        </ode>
      </physics>
    </joint>
    <link name='imu_link'>
      <inertial>
        <pose>0 0 0 0 0 0</pose>
        <mass>0.15</mass>
        <inertia>
          <ixx>0.00001</ixx>
          <ixy>0</ixy>
          <ixz>0</ixz>
          <iyy>0.00002</iyy>
          <iyz>0</iyz>
          <izz>0.00002</izz>
        </inertia>
      </inertial>
      <sensor name="imu_sensor" type="imu">
        <pose>0.00022 -0.00026 0.00973 3.141593 0 0</pose>
        <always_on>1</always_on>
        <update_rate>1000.0</update_rate>
        <plugin name="imu_plugin" filename="libgazebo_ros_imu_sensor.so">
            <topicName>main/imu</topicName>
            <bodyName>imu_link</bodyName>
            <updateRateHz>10.0</updateRateHz>
            <gaussianNoise>0.0</gaussianNoise>
            <xyzOffset>0 0 0</xyzOffset>
            <rpyOffset>0 0 0</rpyOffset>
            <frameName>imu_link</frameName>
            <ros>
                <namespace>frog_v2</namespace>
            </ros>
        </plugin>
      </sensor>
    </link>
    <joint name='imu_joint' type='revolute'>
      <child>imu_link</child>
      <parent>base_link</parent>
      <axis>
        <xyz>0 0 1</xyz>
        <limit>
          <lower>0</lower>
          <upper>0</upper>
          <effort>0</effort>
          <velocity>0</velocity>
        </limit>
        <dynamics>
          <damping>1.0</damping>
        </dynamics>
        <use_parent_model_frame>1</use_parent_model_frame>
      </axis>
      <physics>
        <ode>
          <implicit_spring_damper>1</implicit_spring_damper>
        </ode>
      </physics>
    </joint>
  </model>
</sdf>
